Workbook

Sheet Komoditas besar Nasional
C1: Produksi Komoditas & Nilai Ikan | AL1: RANK | BW1: Produksi Ikan | DF1: FILTER IKAN (NILAI >=250 M)
A2: Jenis Komoditas | B2: Komoditas | C2: Aceh | D2: Sumatera Utara | E2: Sumatera Barat | F2: Riau | G2: Jambi | H2: Sumatera Selatan | I2: Bengkulu | J2: Lampung | K2: Kepulauan Bangka Belitung | L2: Kepulauan Riau | M2: DKI Jakarta | N2: Jawa Barat | O2: Jawa Tengah | P2: DI Yogyakarta | Q2: Jawa Timur | R2: Banten | S2: Bali | T2: Nusa Tenggara Barat | U2: Nusa Tenggara Timur | V2: Kalimantan Barat | W2: Kalimantan Tengah | X2: Kalimantan Selatan | Y2: Kalimantan Timur | Z2: Kalimantan Utara | AA2: Sulawesi Utara | AB2: Sulawesi Tengah | AC2: Sulawesi Selatan | AD2: Sulawesi Tenggara | AE2: Gorontalo | AF2: Sulawesi Barat | AG2: Maluku | AH2: Maluku Utara | AI2: Papua Barat | AJ2: Papua | AL2: Aceh | AM2: Sumatera Utara | AN2: Sumatera Barat | AO2: Riau | AP2: Jambi | AQ2: Sumatera Selatan | AR2: Bengkulu | AS2: Lampung | AT2: Kepulauan Bangka Belitung | AU2: Kepulauan Riau | AV2: DKI Jakarta | AW2: Jawa Barat | AX2: Jawa Tengah | AY2: DI Yogyakarta | AZ2: Jawa Timur | BA2: Banten | BB2: Bali | BC2: Nusa Tenggara Barat | BD2: Nusa Tenggara Timur | BE2: Kalimantan Barat | BF2: Kalimantan Tengah | BG2: Kalimantan Selatan | BH2: Kalimantan Timur | BI2: Kalimantan Utara | BJ2: Sulawesi Utara | BK2: Sulawesi Tengah | BL2: Sulawesi Selatan | BM2: Sulawesi Tenggara | BN2: Gorontalo | BO2: Sulawesi Barat | BP2: Maluku | BQ2: Maluku Utara | BR2: Papua Barat | BS2: Papua | BW2: Aceh | BX2: Sumatera Utara | BY2: Sumatera Barat | BZ2: Riau | CA2: Jambi | CB2: Sumatera Selatan | CC2: Bengkulu | CD2: Lampung | CE2: Kepulauan Bangka Belitung | CF2: Kepulauan Riau | CG2: DKI Jakarta | CH2: Jawa Barat | CI2: Jawa Tengah | CJ2: DI Yogyakarta | CK2: Jawa Timur | CL2: Banten | CM2: Bali | CN2: Nusa Tenggara Barat | CO2: Nusa Tenggara Timur | CP2: Kalimantan Barat | CQ2: Kalimantan Tengah | CR2: Kalimantan Selatan | CS2: Kalimantan Timur | CT2: Kalimantan Utara | CU2: Sulawesi Utara | CV2: Sulawesi Tengah | CW2: Sulawesi Selatan | CX2: Sulawesi Tenggara | CY2: Gorontalo | CZ2: Sulawesi Barat | DA2: Maluku | DB2: Maluku Utara | DC2: Papua Barat | DD2: Papua | DF2: Aceh | DG2: Sumatera Utara | DH2: Sumatera Barat | DI2: Riau | DJ2: Jambi | DK2: Sumatera Selatan | DL2: Bengkulu | DM2: Lampung | DN2: Kepulauan Bangka Belitung | DO2: Kepulauan Riau | DP2: DKI Jakarta | DQ2: Jawa Barat | DR2: Jawa Tengah | DS2: DI Yogyakarta | DT2: Jawa Timur | DU2: Banten | DV2: Bali | DW2: Nusa Tenggara Barat | DX2: Nusa Tenggara Timur | DY2: Kalimantan Barat | DZ2: Kalimantan Tengah | EA2: Kalimantan Selatan | EB2: Kalimantan Timur | EC2: Kalimantan Utara | ED2: Sulawesi Utara | EE2: Sulawesi Tengah | EF2: Sulawesi Selatan | EG2: Sulawesi Tenggara | EH2: Gorontalo | EI2: Sulawesi Barat | EJ2: Maluku | EK2: Maluku Utara | EL2: Papua Barat | EM2: Papua
A3: Tanaman Pangan | B3: Padi (Ton) | C3: =INDEX('raw-all-komoditas'!$B$3:$ZY$37, MATCH('Komoditas besar Nasional'!C$2,'raw-all-komoditas'!$B$3:$B$37,0), MATCH('Komoditas besar Nasional'!$B3,'raw-all-komoditas'!$B$3:$ZY$3,0)) -> 1404235 | D3: =INDEX('raw-all-komoditas'!$B$3:$ZY$37, MATCH('Komoditas besar Nasional'!D$2,'raw-all-komoditas'!$B$3:$B$37,0), MATCH('Komoditas besar Nasional'!$B3,'raw-all-komoditas'!$B$3:$ZY$3,0)) -> 2087474 | E3: =INDEX('raw-all-komoditas'!$B$3:$ZY$37, MATCH('Komoditas besar Nasional'!E$2,'raw-all-komoditas'!$B$3:$B$37,0), MATCH('Komoditas besar Nasional'!$B3,'raw-all-komoditas'!$B$3:$ZY$3,0)) -> 1482469 | F3: =INDEX('raw-all-komoditas'!$B$3:$ZY$37, MATCH('Komoditas besar Nasional'!F$2,'raw-all-komoditas'!$B$3:$B$37,0), MATCH('Komoditas besar Nasional'!$B3,'raw-all-komoditas'!$B$3:$ZY$3,0)) -> 205973 | G3: =INDEX('raw-all-komoditas'!$B$3:$ZY$37, MATCH('Komoditas besar Nasional'!G$2,'raw-all-komoditas'!$B$3:$B$37,0), MATCH('Komoditas besar Nasional'!$B3,'raw-all-komoditas'!$B$3:$ZY$3,0)) -> 275941 | H3: =INDEX('raw-all-komoditas'!$B$3:$ZY$37, MATCH('Komoditas besar Nasional'!H$2,'raw-all-komoditas'!$B$3:$B$37,0), MATCH('Komoditas besar Nasional'!$B3,'raw-all-komoditas'!$B$3:$ZY$3,0)) -> 2832774 | I3: =INDEX('raw-all-komoditas'!$B$3:$ZY$37, MATCH('Komoditas besar Nasional'!I$2,'raw-all-komoditas'!$B$3:$B$37,0), MATCH('Komoditas besar Nasional'!$B3,'raw-all-komoditas'!$B$3:$ZY$3,0)) -> 286684 | J3: =INDEX('raw-all-komoditas'!$B$3:$ZY$37, MATCH('Komoditas besar Nasional'!J$2,'raw-all-komoditas'!$B$3:$B$37,0), MATCH('Komoditas besar Nasional'!$B3,'raw-all-komoditas'!$B$3:$ZY$3,0)) -> 2757898 | ... AJ3: =INDEX('raw-all-komoditas'!$B$3:$ZY$37, MATCH('Komoditas besar Nasional'!AJ$2,'raw-all-komoditas'!$B$3:$B$37,0), MATCH('Komoditas besar Nasional'!$B3,'raw-all-komoditas'!$B$3:$ZY$3,0)) -> 196834 | AL3: =INDEX('rank provinsi to commodity'!$B$3:$ZX$37, MATCH(AL$2,'rank provinsi to commodity'!$B$3:$B$37,0),MATCH($B3,'rank provinsi to commodity'!$B$3:$ZX$3,0)) -> 11 | AM3: =INDEX('rank provinsi to commodity'!$B$3:$ZX$37, MATCH(AM$2,'rank provinsi to commodity'!$B$3:$B$37,0),MATCH($B3,'rank provinsi to commodity'!$B$3:$ZX$3,0)) -> 7 | AN3: =INDEX('rank provinsi to commodity'!$B$3:$ZX$37, MATCH(AN$2,'rank provinsi to commodity'!$B$3:$B$37,0),MATCH($B3,'rank provinsi to commodity'!$B$3:$ZX$3,0)) -> 10 | AO3: =INDEX('rank provinsi to commodity'!$B$3:$ZX$37, MATCH(AO$2,'rank provinsi to commodity'!$B$3:$B$37,0),MATCH($B3,'rank provinsi to commodity'!$B$3:$ZX$3,0)) -> 26 | AP3: =INDEX('rank provinsi to commodity'!$B$3:$ZX$37, MATCH(AP$2,'rank provinsi to commodity'!$B$3:$B$37,0),MATCH($B3,'rank provinsi to commodity'!$B$3:$ZX$3,0)) -> 22 | AQ3: =INDEX('rank provinsi to commodity'!$B$3:$ZX$37, MATCH(AQ$2,'rank provinsi to commodity'!$B$3:$B$37,0),MATCH($B3,'rank provinsi to commodity'!$B$3:$ZX$3,0)) -> 5 | AR3: =INDEX('rank provinsi to commodity'!$B$3:$ZX$37, MATCH(AR$2,'rank provinsi to commodity'!$B$3:$B$37,0),MATCH($B3,'rank provinsi to commodity'!$B$3:$ZX$3,0)) -> 21 | AS3: =INDEX('rank provinsi to commodity'!$B$3:$ZX$37, MATCH(AS$2,'rank provinsi to commodity'!$B$3:$B$37,0),MATCH($B3,'rank provinsi to commodity'!$B$3:$ZX$3,0)) -> 6 | ... BS3: =INDEX('rank provinsi to commodity'!$B$3:$ZX$37, MATCH(BS$2,'rank provinsi to commodity'!$B$3:$B$37,0),MATCH($B3,'rank provinsi to commodity'!$B$3:$ZX$3,0)) -> 27
A4: Tanaman Pangan | B4: Jagung (Ton) | C4: =INDEX('raw-all-komoditas'!$B$3:$ZY$37, MATCH('Komoditas besar Nasional'!C$2,'raw-all-komoditas'!$B$3:$B$37,0), MATCH('Komoditas besar Nasional'!$B4,'raw-all-komoditas'!$B$3:$ZY$3,0)) -> 89771 | D4: =INDEX('raw-all-komoditas'!$B$3:$ZY$37, MATCH('Komoditas besar Nasional'!D$2,'raw-all-komoditas'!$B$3:$B$37,0), MATCH('Komoditas besar Nasional'!$B4,'raw-all-komoditas'!$B$3:$ZY$3,0)) -> 1817094 | E4: =INDEX('raw-all-komoditas'!$B$3:$ZY$37, MATCH('Komoditas besar Nasional'!E$2,'raw-all-komoditas'!$B$3:$B$37,0), MATCH('Komoditas besar Nasional'!$B4,'raw-all-komoditas'!$B$3:$ZY$3,0)) -> 669898 | F4: =INDEX('raw-all-komoditas'!$B$3:$ZY$37, MATCH('Komoditas besar Nasional'!F$2,'raw-all-komoditas'!$B$3:$B$37,0), MATCH('Komoditas besar Nasional'!$B4,'raw-all-komoditas'!$B$3:$ZY$3,0)) -> 932 | G4: =INDEX('raw-all-komoditas'!$B$3:$ZY$37, MATCH('Komoditas besar Nasional'!G$2,'raw-all-komoditas'!$B$3:$B$37,0), MATCH('Komoditas besar Nasional'!$B4,'raw-all-komoditas'!$B$3:$ZY$3,0)) -> 6391 | H4: =INDEX('raw-all-komoditas'!$B$3:$ZY$37, MATCH('Komoditas besar Nasional'!H$2,'raw-all-komoditas'!$B$3:$B$37,0), MATCH('Komoditas besar Nasional'!$B4,'raw-all-komoditas'!$B$3:$ZY$3,0)) -> 385042 | I4: =INDEX('raw-all-komoditas'!$B$3:$ZY$37, MATCH('Komoditas besar Nasional'!I$2,'raw-all-komoditas'!$B$3:$B$37,0), MATCH('Komoditas besar Nasional'!$B4,'raw-all-komoditas'!$B$3:$ZY$3,0)) -> 68206 | J4: =INDEX('raw-all-komoditas'!$B$3:$ZY$37, MATCH('Komoditas besar Nasional'!J$2,'raw-all-komoditas'!$B$3:$B$37,0), MATCH('Komoditas besar Nasional'!$B4,'raw-all-komoditas'!$B$3:$ZY$3,0)) -> 1492915 | ... AJ4: =INDEX('raw-all-komoditas'!$B$3:$ZY$37, MATCH('Komoditas besar Nasional'!AJ$2,'raw-all-komoditas'!$B$3:$B$37,0), MATCH('Komoditas besar Nasional'!$B4,'raw-all-komoditas'!$B$3:$ZY$3,0)) -> 17394 | AL4: =INDEX('rank provinsi to commodity'!$B$3:$ZX$37, MATCH(AL$2,'rank provinsi to commodity'!$B$3:$B$37,0),MATCH($B4,'rank provinsi to commodity'!$B$3:$ZX$3,0)) -> 17 | AM4: =INDEX('rank provinsi to commodity'!$B$3:$ZX$37, MATCH(AM$2,'rank provinsi to commodity'!$B$3:$B$37,0),MATCH($B4,'rank provinsi to commodity'!$B$3:$ZX$3,0)) -> 3 | AN4: =INDEX('rank provinsi to commodity'!$B$3:$ZX$37, MATCH(AN$2,'rank provinsi to commodity'!$B$3:$B$37,0),MATCH($B4,'rank provinsi to commodity'!$B$3:$ZX$3,0)) -> 9 | AO4: =INDEX('rank provinsi to commodity'!$B$3:$ZX$37, MATCH(AO$2,'rank provinsi to commodity'!$B$3:$B$37,0),MATCH($B4,'rank provinsi to commodity'!$B$3:$ZX$3,0)) -> 31 | AP4: =INDEX('rank provinsi to commodity'!$B$3:$ZX$37, MATCH(AP$2,'rank provinsi to commodity'!$B$3:$B$37,0),MATCH($B4,'rank provinsi to commodity'!$B$3:$ZX$3,0)) -> 28 | AQ4: =INDEX('rank provinsi to commodity'!$B$3:$ZX$37, MATCH(AQ$2,'rank provinsi to commodity'!$B$3:$B$37,0),MATCH($B4,'rank provinsi to commodity'!$B$3:$ZX$3,0)) -> 10 | AR4: =INDEX('rank provinsi to commodity'!$B$3:$ZX$37, MATCH(AR$2,'rank provinsi to commodity'!$B$3:$B$37,0),MATCH($B4,'rank provinsi to commodity'!$B$3:$ZX$3,0)) -> 19 | AS4: =INDEX('rank provinsi to commodity'!$B$3:$ZX$37, MATCH(AS$2,'rank provinsi to commodity'!$B$3:$B$37,0),MATCH($B4,'rank provinsi to commodity'!$B$3:$ZX$3,0)) -> 5 | ... BS4: =INDEX('rank provinsi to commodity'!$B$3:$ZX$37, MATCH(BS$2,'rank provinsi to commodity'!$B$3:$B$37,0),MATCH($B4,'rank provinsi to commodity'!$B$3:$ZX$3,0)) -> 24
A5: Tanaman Pangan | B5: Kedelai (Ton) | C5: =INDEX('raw-all-komoditas'!$B$3:$ZY$37, MATCH('Komoditas besar Nasional'!C$2,'raw-all-komoditas'!$B$3:$B$37,0), MATCH('Komoditas besar Nasional'!$B5,'raw-all-komoditas'!$B$3:$ZY$3,0)) -> 11604 | D5: =INDEX('raw-all-komoditas'!$B$3:$ZY$37, MATCH('Komoditas besar Nasional'!D$2,'raw-all-komoditas'!$B$3:$B$37,0), MATCH('Komoditas besar Nasional'!$B5,'raw-all-komoditas'!$B$3:$ZY$3,0)) -> 15993 | E5: =INDEX('raw-all-komoditas'!$B$3:$ZY$37, MATCH('Komoditas besar Nasional'!E$2,'raw-all-komoditas'!$B$3:$B$37,0), MATCH('Komoditas besar Nasional'!$B5,'raw-all-komoditas'!$B$3:$ZY$3,0)) -> 23 | F5: =INDEX('raw-all-komoditas'!$B$3:$ZY$37, MATCH('Komoditas besar Nasional'!F$2,'raw-all-komoditas'!$B$3:$B$37,0), MATCH('Komoditas besar Nasional'!$B5,'raw-all-komoditas'!$B$3:$ZY$3,0)) -> 364 | G5: =INDEX('raw-all-komoditas'!$B$3:$ZY$37, MATCH('Komoditas besar Nasional'!G$2,'raw-all-komoditas'!$B$3:$B$37,0), MATCH('Komoditas besar Nasional'!$B5,'raw-all-komoditas'!$B$3:$ZY$3,0)) -> 4512 | H5: =INDEX('raw-all-komoditas'!$B$3:$ZY$37, MATCH('Komoditas besar Nasional'!H$2,'raw-all-komoditas'!$B$3:$B$37,0), MATCH('Komoditas besar Nasional'!$B5,'raw-all-komoditas'!$B$3:$ZY$3,0)) -> 210 | I5: =INDEX('raw-all-komoditas'!$B$3:$ZY$37, MATCH('Komoditas besar Nasional'!I$2,'raw-all-komoditas'!$B$3:$B$37,0), MATCH('Komoditas besar Nasional'!$B5,'raw-all-komoditas'!$B$3:$ZY$3,0)) -> 999 | J5: =INDEX('raw-all-komoditas'!$B$3:$ZY$37, MATCH('Komoditas besar Nasional'!J$2,'raw-all-komoditas'!$B$3:$B$37,0), MATCH('Komoditas besar Nasional'!$B5,'raw-all-komoditas'!$B$3:$ZY$3,0)) -> 7412 | ... AJ5: =INDEX('raw-all-komoditas'!$B$3:$ZY$37, MATCH('Komoditas besar Nasional'!AJ$2,'raw-all-komoditas'!$B$3:$B$37,0), MATCH('Komoditas besar Nasional'!$B5,'raw-all-komoditas'!$B$3:$ZY$3,0)) -> 75 | AL5: =INDEX('rank provinsi to commodity'!$B$3:$ZX$37, MATCH(AL$2,'rank provinsi to commodity'!$B$3:$B$37,0),MATCH($B5,'rank provinsi to commodity'!$B$3:$ZX$3,0)) -> 6 | AM5: =INDEX('rank provinsi to commodity'!$B$3:$ZX$37, MATCH(AM$2,'rank provinsi to commodity'!$B$3:$B$37,0),MATCH($B5,'rank provinsi to commodity'!$B$3:$ZX$3,0)) -> 5 | AN5: =INDEX('rank provinsi to commodity'!$B$3:$ZX$37, MATCH(AN$2,'rank provinsi to commodity'!$B$3:$B$37,0),MATCH($B5,'rank provinsi to commodity'!$B$3:$ZX$3,0)) -> 29 | AO5: =INDEX('rank provinsi to commodity'!$B$3:$ZX$37, MATCH(AO$2,'rank provinsi to commodity'!$B$3:$B$37,0),MATCH($B5,'rank provinsi to commodity'!$B$3:$ZX$3,0)) -> 20 | AP5: =INDEX('rank provinsi to commodity'!$B$3:$ZX$37, MATCH(AP$2,'rank provinsi to commodity'!$B$3:$B$37,0),MATCH($B5,'rank provinsi to commodity'!$B$3:$ZX$3,0)) -> 13 | AQ5: =INDEX('rank provinsi to commodity'!$B$3:$ZX$37, MATCH(AQ$2,'rank provinsi to commodity'!$B$3:$B$37,0),MATCH($B5,'rank provinsi to commodity'!$B$3:$ZX$3,0)) -> 21 | AR5: =INDEX('rank provinsi to commodity'!$B$3:$ZX$37, MATCH(AR$2,'rank provinsi to commodity'!$B$3:$B$37,0),MATCH($B5,'rank provinsi to commodity'!$B$3:$ZX$3,0)) -> 19 | AS5: =INDEX('rank provinsi to commodity'!$B$3:$ZX$37, MATCH(AS$2,'rank provinsi to commodity'!$B$3:$B$37,0),MATCH($B5,'rank provinsi to commodity'!$B$3:$ZX$3,0)) -> 11 | ... BS5: =INDEX('rank provinsi to commodity'!$B$3:$ZX$37, MATCH(BS$2,'rank provinsi to commodity'!$B$3:$B$37,0),MATCH($B5,'rank provinsi to commodity'!$B$3:$ZX$3,0)) -> 26
A6: Tanaman Pangan | B6: Kacang Tanah (Ton) | C6: =INDEX('raw-all-komoditas'!$B$3:$ZY$37, MATCH('Komoditas besar Nasional'!C$2,'raw-all-komoditas'!$B$3:$B$37,0), MATCH('Komoditas besar Nasional'!$B6,'raw-all-komoditas'!$B$3:$ZY$3,0)) -> 1835 | D6: =INDEX('raw-all-komoditas'!$B$3:$ZY$37, MATCH('Komoditas besar Nasional'!D$2,'raw-all-komoditas'!$B$3:$B$37,0), MATCH('Komoditas besar Nasional'!$B6,'raw-all-komoditas'!$B$3:$ZY$3,0)) -> 7355 | E6: =INDEX('raw-all-komoditas'!$B$3:$ZY$37, MATCH('Komoditas besar Nasional'!E$2,'raw-all-komoditas'!$B$3:$B$37,0), MATCH('Komoditas besar Nasional'!$B6,'raw-all-komoditas'!$B$3:$ZY$3,0)) -> 2915 | F6: =INDEX('raw-all-komoditas'!$B$3:$ZY$37, MATCH('Komoditas besar Nasional'!F$2,'raw-all-komoditas'!$B$3:$B$37,0), MATCH('Komoditas besar Nasional'!$B6,'raw-all-komoditas'!$B$3:$ZY$3,0)) -> 418 | G6: =INDEX('raw-all-komoditas'!$B$3:$ZY$37, MATCH('Komoditas besar Nasional'!G$2,'raw-all-komoditas'!$B$3:$B$37,0), MATCH('Komoditas besar Nasional'!$B6,'raw-all-komoditas'!$B$3:$ZY$3,0)) -> 1460 | H6: =INDEX('raw-all-komoditas'!$B$3:$ZY$37, MATCH('Komoditas besar Nasional'!H$2,'raw-all-komoditas'!$B$3:$B$37,0), MATCH('Komoditas besar Nasional'!$B6,'raw-all-komoditas'!$B$3:$ZY$3,0)) -> 1357 | I6: =INDEX('raw-all-komoditas'!$B$3:$ZY$37, MATCH('Komoditas besar Nasional'!I$2,'raw-all-komoditas'!$B$3:$B$37,0), MATCH('Komoditas besar Nasional'!$B6,'raw-all-komoditas'!$B$3:$ZY$3,0)) -> 1638 | J6: =INDEX('raw-all-komoditas'!$B$3:$ZY$37, MATCH('Komoditas besar Nasional'!J$2,'raw-all-komoditas'!$B$3:$B$37,0), MATCH('Komoditas besar Nasional'!$B6,'raw-all-komoditas'!$B$3:$ZY$3,0)) -> 1750 | ... AJ6: =INDEX('raw-all-komoditas'!$B$3:$ZY$37, MATCH('Komoditas besar Nasional'!AJ$2,'raw-all-komoditas'!$B$3:$B$37,0), MATCH('Komoditas besar Nasional'!$B6,'raw-all-komoditas'!$B$3:$ZY$3,0)) -> 0 | AL6: =INDEX('rank provinsi to commodity'!$B$3:$ZX$37, MATCH(AL$2,'rank provinsi to commodity'!$B$3:$B$37,0),MATCH($B6,'rank provinsi to commodity'!$B$3:$ZX$3,0)) -> 13 | AM6: =INDEX('rank provinsi to commodity'!$B$3:$ZX$37, MATCH(AM$2,'rank provinsi to commodity'!$B$3:$B$37,0),MATCH($B6,'rank provinsi to commodity'!$B$3:$ZX$3,0)) -> 8 | AN6: =INDEX('rank provinsi to commodity'!$B$3:$ZX$37, MATCH(AN$2,'rank provinsi to commodity'!$B$3:$B$37,0),MATCH($B6,'rank provinsi to commodity'!$B$3:$ZX$3,0)) -> 10 | AO6: =INDEX('rank provinsi to commodity'!$B$3:$ZX$37, MATCH(AO$2,'rank provinsi to commodity'!$B$3:$B$37,0),MATCH($B6,'rank provinsi to commodity'!$B$3:$ZX$3,0)) -> 22 | AP6: =INDEX('rank provinsi to commodity'!$B$3:$ZX$37, MATCH(AP$2,'rank provinsi to commodity'!$B$3:$B$37,0),MATCH($B6,'rank provinsi to commodity'!$B$3:$ZX$3,0)) -> 19 | AQ6: =INDEX('rank provinsi to commodity'!$B$3:$ZX$37, MATCH(AQ$2,'rank provinsi to commodity'!$B$3:$B$37,0),MATCH($B6,'rank provinsi to commodity'!$B$3:$ZX$3,0)) -> 20 | AR6: =INDEX('rank provinsi to commodity'!$B$3:$ZX$37, MATCH(AR$2,'rank provinsi to commodity'!$B$3:$B$37,0),MATCH($B6,'rank provinsi to commodity'!$B$3:$ZX$3,0)) -> 17 | AS6: =INDEX('rank provinsi to commodity'!$B$3:$ZX$37, MATCH(AS$2,'rank provinsi to commodity'!$B$3:$B$37,0),MATCH($B6,'rank provinsi to commodity'!$B$3:$ZX$3,0)) -> 15 | ... BS6: =INDEX('rank provinsi to commodity'!$B$3:$ZX$37, MATCH(BS$2,'rank provinsi to commodity'!$B$3:$B$37,0),MATCH($B6,'rank provinsi to commodity'!$B$3:$ZX$3,0)) -> 33
A7: Tanaman Pangan | B7: Kacang Hijau (Ton) | C7: =INDEX('raw-all-komoditas'!$B$3:$ZY$37, MATCH('Komoditas besar Nasional'!C$2,'raw-all-komoditas'!$B$3:$B$37,0), MATCH('Komoditas besar Nasional'!$B7,'raw-all-komoditas'!$B$3:$ZY$3,0)) -> 354 | D7: =INDEX('raw-all-komoditas'!$B$3:$ZY$37, MATCH('Komoditas besar Nasional'!D$2,'raw-all-komoditas'!$B$3:$B$37,0), MATCH('Komoditas besar Nasional'!$B7,'raw-all-komoditas'!$B$3:$ZY$3,0)) -> 2237 | E7: =INDEX('raw-all-komoditas'!$B$3:$ZY$37, MATCH('Komoditas besar Nasional'!E$2,'raw-all-komoditas'!$B$3:$B$37,0), MATCH('Komoditas besar Nasional'!$B7,'raw-all-komoditas'!$B$3:$ZY$3,0)) -> 251 | F7: =INDEX('raw-all-komoditas'!$B$3:$ZY$37, MATCH('Komoditas besar Nasional'!F$2,'raw-all-komoditas'!$B$3:$B$37,0), MATCH('Komoditas besar Nasional'!$B7,'raw-all-komoditas'!$B$3:$ZY$3,0)) -> 127 | G7: =INDEX('raw-all-komoditas'!$B$3:$ZY$37, MATCH('Komoditas besar Nasional'!G$2,'raw-all-komoditas'!$B$3:$B$37,0), MATCH('Komoditas besar Nasional'!$B7,'raw-all-komoditas'!$B$3:$ZY$3,0)) -> 68 | H7: =INDEX('raw-all-komoditas'!$B$3:$ZY$37, MATCH('Komoditas besar Nasional'!H$2,'raw-all-komoditas'!$B$3:$B$37,0), MATCH('Komoditas besar Nasional'!$B7,'raw-all-komoditas'!$B$3:$ZY$3,0)) -> 146 | I7: =INDEX('raw-all-komoditas'!$B$3:$ZY$37, MATCH('Komoditas besar Nasional'!I$2,'raw-all-komoditas'!$B$3:$B$37,0), MATCH('Komoditas besar Nasional'!$B7,'raw-all-komoditas'!$B$3:$ZY$3,0)) -> 206 | J7: =INDEX('raw-all-komoditas'!$B$3:$ZY$37, MATCH('Komoditas besar Nasional'!J$2,'raw-all-komoditas'!$B$3:$B$37,0), MATCH('Komoditas besar Nasional'!$B7,'raw-all-komoditas'!$B$3:$ZY$3,0)) -> 443 | ... AJ7: =INDEX('raw-all-komoditas'!$B$3:$ZY$37, MATCH('Komoditas besar Nasional'!AJ$2,'raw-all-komoditas'!$B$3:$B$37,0), MATCH('Komoditas besar Nasional'!$B7,'raw-all-komoditas'!$B$3:$ZY$3,0)) -> 0 | AL7: =INDEX('rank provinsi to commodity'!$B$3:$ZX$37, MATCH(AL$2,'rank provinsi to commodity'!$B$3:$B$37,0),MATCH($B7,'rank provinsi to commodity'!$B$3:$ZX$3,0)) -> 10 | AM7: =INDEX('rank provinsi to commodity'!$B$3:$ZX$37, MATCH(AM$2,'rank provinsi to commodity'!$B$3:$B$37,0),MATCH($B7,'rank provinsi to commodity'!$B$3:$ZX$3,0)) -> 7 | AN7: =INDEX('rank provinsi to commodity'!$B$3:$ZX$37, MATCH(AN$2,'rank provinsi to commodity'!$B$3:$B$37,0),MATCH($B7,'rank provinsi to commodity'!$B$3:$ZX$3,0)) -> 13 | AO7: =INDEX('rank provinsi to commodity'!$B$3:$ZX$37, MATCH(AO$2,'rank provinsi to commodity'!$B$3:$B$37,0),MATCH($B7,'rank provinsi to commodity'!$B$3:$ZX$3,0)) -> 19 | AP7: =INDEX('rank provinsi to commodity'!$B$3:$ZX$37, MATCH(AP$2,'rank provinsi to commodity'!$B$3:$B$37,0),MATCH($B7,'rank provinsi to commodity'!$B$3:$ZX$3,0)) -> 21 | AQ7: =INDEX('rank provinsi to commodity'!$B$3:$ZX$37, MATCH(AQ$2,'rank provinsi to commodity'!$B$3:$B$37,0),MATCH($B7,'rank provinsi to commodity'!$B$3:$ZX$3,0)) -> 18 | AR7: =INDEX('rank provinsi to commodity'!$B$3:$ZX$37, MATCH(AR$2,'rank provinsi to commodity'!$B$3:$B$37,0),MATCH($B7,'rank provinsi to commodity'!$B$3:$ZX$3,0)) -> 15 | AS7: =INDEX('rank provinsi to commodity'!$B$3:$ZX$37, MATCH(AS$2,'rank provinsi to commodity'!$B$3:$B$37,0),MATCH($B7,'rank provinsi to commodity'!$B$3:$ZX$3,0)) -> 9 | ... BS7: =INDEX('rank provinsi to commodity'!$B$3:$ZX$37, MATCH(BS$2,'rank provinsi to commodity'!$B$3:$B$37,0),MATCH($B7,'rank provinsi to commodity'!$B$3:$ZX$3,0)) -> 30
A8: Tanaman Pangan | B8: Ubi Kayu (Ton) | C8: =INDEX('raw-all-komoditas'!$B$3:$ZY$37, MATCH('Komoditas besar Nasional'!C$2,'raw-all-komoditas'!$B$3:$B$37,0), MATCH('Komoditas besar Nasional'!$B8,'raw-all-komoditas'!$B$3:$ZY$3,0)) -> 36087 | D8: =INDEX('raw-all-komoditas'!$B$3:$ZY$37, MATCH('Komoditas besar Nasional'!D$2,'raw-all-komoditas'!$B$3:$B$37,0), MATCH('Komoditas besar Nasional'!$B8,'raw-all-komoditas'!$B$3:$ZY$3,0)) -> 1099641 | E8: =INDEX('raw-all-komoditas'!$B$3:$ZY$37, MATCH('Komoditas besar Nasional'!E$2,'raw-all-komoditas'!$B$3:$B$37,0), MATCH('Komoditas besar Nasional'!$B8,'raw-all-komoditas'!$B$3:$ZY$3,0)) -> 131981 | F8: =INDEX('raw-all-komoditas'!$B$3:$ZY$37, MATCH('Komoditas besar Nasional'!F$2,'raw-all-komoditas'!$B$3:$B$37,0), MATCH('Komoditas besar Nasional'!$B8,'raw-all-komoditas'!$B$3:$ZY$3,0)) -> 57786 | G8: =INDEX('raw-all-komoditas'!$B$3:$ZY$37, MATCH('Komoditas besar Nasional'!G$2,'raw-all-komoditas'!$B$3:$B$37,0), MATCH('Komoditas besar Nasional'!$B8,'raw-all-komoditas'!$B$3:$ZY$3,0)) -> 54739 | H8: =INDEX('raw-all-komoditas'!$B$3:$ZY$37, MATCH('Komoditas besar Nasional'!H$2,'raw-all-komoditas'!$B$3:$B$37,0), MATCH('Komoditas besar Nasional'!$B8,'raw-all-komoditas'!$B$3:$ZY$3,0)) -> 207205 | I8: =INDEX('raw-all-komoditas'!$B$3:$ZY$37, MATCH('Komoditas besar Nasional'!I$2,'raw-all-komoditas'!$B$3:$B$37,0), MATCH('Komoditas besar Nasional'!$B8,'raw-all-komoditas'!$B$3:$ZY$3,0)) -> 25730 | J8: =INDEX('raw-all-komoditas'!$B$3:$ZY$37, MATCH('Komoditas besar Nasional'!J$2,'raw-all-komoditas'!$B$3:$B$37,0), MATCH('Komoditas besar Nasional'!$B8,'raw-all-komoditas'!$B$3:$ZY$3,0)) -> 7227672 | ... AJ8: =INDEX('raw-all-komoditas'!$B$3:$ZY$37, MATCH('Komoditas besar Nasional'!AJ$2,'raw-all-komoditas'!$B$3:$B$37,0), MATCH('Komoditas besar Nasional'!$B8,'raw-all-komoditas'!$B$3:$ZY$3,0)) -> 0 | AL8: =INDEX('rank provinsi to commodity'!$B$3:$ZX$37, MATCH(AL$2,'rank provinsi to commodity'!$B$3:$B$37,0),MATCH($B8,'rank provinsi to commodity'!$B$3:$ZX$3,0)) -> 21 | AM8: =INDEX('rank provinsi to commodity'!$B$3:$ZX$37, MATCH(AM$2,'rank provinsi to commodity'!$B$3:$B$37,0),MATCH($B8,'rank provinsi to commodity'!$B$3:$ZX$3,0)) -> 5 | AN8: =INDEX('rank provinsi to commodity'!$B$3:$ZX$37, MATCH(AN$2,'rank provinsi to commodity'!$B$3:$B$37,0),MATCH($B8,'rank provinsi to commodity'!$B$3:$ZX$3,0)) -> 11 | AO8: =INDEX('rank provinsi to commodity'!$B$3:$ZX$37, MATCH(AO$2,'rank provinsi to commodity'!$B$3:$B$37,0),MATCH($B8,'rank provinsi to commodity'!$B$3:$ZX$3,0)) -> 14 | AP8: =INDEX('rank provinsi to commodity'!$B$3:$ZX$37, MATCH(AP$2,'rank provinsi to commodity'!$B$3:$B$37,0),MATCH($B8,'rank provinsi to commodity'!$B$3:$ZX$3,0)) -> 15 | AQ8: =INDEX('rank provinsi to commodity'!$B$3:$ZX$37, MATCH(AQ$2,'rank provinsi to commodity'!$B$3:$B$37,0),MATCH($B8,'rank provinsi to commodity'!$B$3:$ZX$3,0)) -> 9 | AR8: =INDEX('rank provinsi to commodity'!$B$3:$ZX$37, MATCH(AR$2,'rank provinsi to commodity'!$B$3:$B$37,0),MATCH($B8,'rank provinsi to commodity'!$B$3:$ZX$3,0)) -> 27 | AS8: =INDEX('rank provinsi to commodity'!$B$3:$ZX$37, MATCH(AS$2,'rank provinsi to commodity'!$B$3:$B$37,0),MATCH($B8,'rank provinsi to commodity'!$B$3:$ZX$3,0)) -> 1 | ... BS8: =INDEX('rank provinsi to commodity'!$B$3:$ZX$37, MATCH(BS$2,'rank provinsi to commodity'!$B$3:$B$37,0),MATCH($B8,'rank provinsi to commodity'!$B$3:$ZX$3,0)) -> 33
A9: Tanaman Pangan | B9: Ubi Jalar (Ton) | C9: =INDEX('raw-all-komoditas'!$B$3:$ZY$37, MATCH('Komoditas besar Nasional'!C$2,'raw-all-komoditas'!$B$3:$B$37,0), MATCH('Komoditas besar Nasional'!$B9,'raw-all-komoditas'!$B$3:$ZY$3,0)) -> 7207 | D9: =INDEX('raw-all-komoditas'!$B$3:$ZY$37, MATCH('Komoditas besar Nasional'!D$2,'raw-all-komoditas'!$B$3:$B$37,0), MATCH('Komoditas besar Nasional'!$B9,'raw-all-komoditas'!$B$3:$ZY$3,0)) -> 92617 | E9: =INDEX('raw-all-komoditas'!$B$3:$ZY$37, MATCH('Komoditas besar Nasional'!E$2,'raw-all-komoditas'!$B$3:$B$37,0), MATCH('Komoditas besar Nasional'!$B9,'raw-all-komoditas'!$B$3:$ZY$3,0)) -> 130296 | F9: =INDEX('raw-all-komoditas'!$B$3:$ZY$37, MATCH('Komoditas besar Nasional'!F$2,'raw-all-komoditas'!$B$3:$B$37,0), MATCH('Komoditas besar Nasional'!$B9,'raw-all-komoditas'!$B$3:$ZY$3,0)) -> 3378 | G9: =INDEX('raw-all-komoditas'!$B$3:$ZY$37, MATCH('Komoditas besar Nasional'!G$2,'raw-all-komoditas'!$B$3:$B$37,0), MATCH('Komoditas besar Nasional'!$B9,'raw-all-komoditas'!$B$3:$ZY$3,0)) -> 25817 | H9: =INDEX('raw-all-komoditas'!$B$3:$ZY$37, MATCH('Komoditas besar Nasional'!H$2,'raw-all-komoditas'!$B$3:$B$37,0), MATCH('Komoditas besar Nasional'!$B9,'raw-all-komoditas'!$B$3:$ZY$3,0)) -> 29054 | I9: =INDEX('raw-all-komoditas'!$B$3:$ZY$37, MATCH('Komoditas besar Nasional'!I$2,'raw-all-komoditas'!$B$3:$B$37,0), MATCH('Komoditas besar Nasional'!$B9,'raw-all-komoditas'!$B$3:$ZY$3,0)) -> 24234 | J9: =INDEX('raw-all-komoditas'!$B$3:$ZY$37, MATCH('Komoditas besar Nasional'!J$2,'raw-all-komoditas'!$B$3:$B$37,0), MATCH('Komoditas besar Nasional'!$B9,'raw-all-komoditas'!$B$3:$ZY$3,0)) -> 29589 | ... AJ9: =INDEX('raw-all-komoditas'!$B$3:$ZY$37, MATCH('Komoditas besar Nasional'!AJ$2,'raw-all-komoditas'!$B$3:$B$37,0), MATCH('Komoditas besar Nasional'!$B9,'raw-all-komoditas'!$B$3:$ZY$3,0)) -> 0 | AL9: =INDEX('rank provinsi to commodity'!$B$3:$ZX$37, MATCH(AL$2,'rank provinsi to commodity'!$B$3:$B$37,0),MATCH($B9,'rank provinsi to commodity'!$B$3:$ZX$3,0)) -> 21 | AM9: =INDEX('rank provinsi to commodity'!$B$3:$ZX$37, MATCH(AM$2,'rank provinsi to commodity'!$B$3:$B$37,0),MATCH($B9,'rank provinsi to commodity'!$B$3:$ZX$3,0)) -> 5 | AN9: =INDEX('rank provinsi to commodity'!$B$3:$ZX$37, MATCH(AN$2,'rank provinsi to commodity'!$B$3:$B$37,0),MATCH($B9,'rank provinsi to commodity'!$B$3:$ZX$3,0)) -> 3 | AO9: =INDEX('rank provinsi to commodity'!$B$3:$ZX$37, MATCH(AO$2,'rank provinsi to commodity'!$B$3:$B$37,0),MATCH($B9,'rank provinsi to commodity'!$B$3:$ZX$3,0)) -> 27 | AP9: =INDEX('rank provinsi to commodity'!$B$3:$ZX$37, MATCH(AP$2,'rank provinsi to commodity'!$B$3:$B$37,0),MATCH($B9,'rank provinsi to commodity'!$B$3:$ZX$3,0)) -> 10 | AQ9: =INDEX('rank provinsi to commodity'!$B$3:$ZX$37, MATCH(AQ$2,'rank provinsi to commodity'!$B$3:$B$37,0),MATCH($B9,'rank provinsi to commodity'!$B$3:$ZX$3,0)) -> 9 | AR9: =INDEX('rank provinsi to commodity'!$B$3:$ZX$37, MATCH(AR$2,'rank provinsi to commodity'!$B$3:$B$37,0),MATCH($B9,'rank provinsi to commodity'!$B$3:$ZX$3,0)) -> 11 | AS9: =INDEX('rank provinsi to commodity'!$B$3:$ZX$37, MATCH(AS$2,'rank provinsi to commodity'!$B$3:$B$37,0),MATCH($B9,'rank provinsi to commodity'!$B$3:$ZX$3,0)) -> 8 | ... BS9: =INDEX('rank provinsi to commodity'!$B$3:$ZX$37, MATCH(BS$2,'rank provinsi to commodity'!$B$3:$B$37,0),MATCH($B9,'rank provinsi to commodity'!$B$3:$ZX$3,0)) -> 33
A10: Tanaman Sayuran | B10: Buncis (Ton) | C10: =INDEX('raw-all-komoditas'!$B$3:$ZY$37, MATCH('Komoditas besar Nasional'!C$2,'raw-all-komoditas'!$B$3:$B$37,0), MATCH('Komoditas besar Nasional'!$B10,'raw-all-komoditas'!$B$3:$ZY$3,0)) -> 625 | D10: =INDEX('raw-all-komoditas'!$B$3:$ZY$37, MATCH('Komoditas besar Nasional'!D$2,'raw-all-komoditas'!$B$3:$B$37,0), MATCH('Komoditas besar Nasional'!$B10,'raw-all-komoditas'!$B$3:$ZY$3,0)) -> 48328 | E10: =INDEX('raw-all-komoditas'!$B$3:$ZY$37, MATCH('Komoditas besar Nasional'!E$2,'raw-all-komoditas'!$B$3:$B$37,0), MATCH('Komoditas besar Nasional'!$B10,'raw-all-komoditas'!$B$3:$ZY$3,0)) -> 41404 | F10: =INDEX('raw-all-komoditas'!$B$3:$ZY$37, MATCH('Komoditas besar Nasional'!F$2,'raw-all-komoditas'!$B$3:$B$37,0), MATCH('Komoditas besar Nasional'!$B10,'raw-all-komoditas'!$B$3:$ZY$3,0)) -> 26 | G10: =INDEX('raw-all-komoditas'!$B$3:$ZY$37, MATCH('Komoditas besar Nasional'!G$2,'raw-all-komoditas'!$B$3:$B$37,0), MATCH('Komoditas besar Nasional'!$B10,'raw-all-komoditas'!$B$3:$ZY$3,0)) -> 6647 | H10: =INDEX('raw-all-komoditas'!$B$3:$ZY$37, MATCH('Komoditas besar Nasional'!H$2,'raw-all-komoditas'!$B$3:$B$37,0), MATCH('Komoditas besar Nasional'!$B10,'raw-all-komoditas'!$B$3:$ZY$3,0)) -> 2949 | I10: =INDEX('raw-all-komoditas'!$B$3:$ZY$37, MATCH('Komoditas besar Nasional'!I$2,'raw-all-komoditas'!$B$3:$B$37,0), MATCH('Komoditas besar Nasional'!$B10,'raw-all-komoditas'!$B$3:$ZY$3,0)) -> 29093 | J10: =INDEX('raw-all-komoditas'!$B$3:$ZY$37, MATCH('Komoditas besar Nasional'!J$2,'raw-all-komoditas'!$B$3:$B$37,0), MATCH('Komoditas besar Nasional'!$B10,'raw-all-komoditas'!$B$3:$ZY$3,0)) -> 5594 | ... AJ10: =INDEX('raw-all-komoditas'!$B$3:$ZY$37, MATCH('Komoditas besar Nasional'!AJ$2,'raw-all-komoditas'!$B$3:$B$37,0), MATCH('Komoditas besar Nasional'!$B10,'raw-all-komoditas'!$B$3:$ZY$3,0)) -> 1302 | AL10: =INDEX('rank provinsi to commodity'!$B$3:$ZX$37, MATCH(AL$2,'rank provinsi to commodity'!$B$3:$B$37,0),MATCH($B10,'rank provinsi to commodity'!$B$3:$ZX$3,0)) -> 25 | AM10: =INDEX('rank provinsi to commodity'!$B$3:$ZX$37, MATCH(AM$2,'rank provinsi to commodity'!$B$3:$B$37,0),MATCH($B10,'rank provinsi to commodity'!$B$3:$ZX$3,0)) -> 2 | AN10: =INDEX('rank provinsi to commodity'!$B$3:$ZX$37, MATCH(AN$2,'rank provinsi to commodity'!$B$3:$B$37,0),MATCH($B10,'rank provinsi to commodity'!$B$3:$ZX$3,0)) -> 3 | AO10: =INDEX('rank provinsi to commodity'!$B$3:$ZX$37, MATCH(AO$2,'rank provinsi to commodity'!$B$3:$B$37,0),MATCH($B10,'rank provinsi to commodity'!$B$3:$ZX$3,0)) -> 31 | AP10: =INDEX('rank provinsi to commodity'!$B$3:$ZX$37, MATCH(AP$2,'rank provinsi to commodity'!$B$3:$B$37,0),MATCH($B10,'rank provinsi to commodity'!$B$3:$ZX$3,0)) -> 7 | AQ10: =INDEX('rank provinsi to commodity'!$B$3:$ZX$37, MATCH(AQ$2,'rank provinsi to commodity'!$B$3:$B$37,0),MATCH($B10,'rank provinsi to commodity'!$B$3:$ZX$3,0)) -> 14 | AR10: =INDEX('rank provinsi to commodity'!$B$3:$ZX$37, MATCH(AR$2,'rank provinsi to commodity'!$B$3:$B$37,0),MATCH($B10,'rank provinsi to commodity'!$B$3:$ZX$3,0)) -> 5 | AS10: =INDEX('rank provinsi to commodity'!$B$3:$ZX$37, MATCH(AS$2,'rank provinsi to commodity'!$B$3:$B$37,0),MATCH($B10,'rank provinsi to commodity'!$B$3:$ZX$3,0)) -> 8 | ... BS10: =INDEX('rank provinsi to commodity'!$B$3:$ZX$37, MATCH(BS$2,'rank provinsi to commodity'!$B$3:$B$37,0),MATCH($B10,'rank provinsi to commodity'!$B$3:$ZX$3,0)) -> 19
A11: Tanaman Sayuran | B11: Bawang Merah (Ton) | C11: =INDEX('raw-all-komoditas'!$B$3:$ZY$37, MATCH('Komoditas besar Nasional'!C$2,'raw-all-komoditas'!$B$3:$B$37,0), MATCH('Komoditas besar Nasional'!$B11,'raw-all-komoditas'!$B$3:$ZY$3,0)) -> 13673 | D11: =INDEX('raw-all-komoditas'!$B$3:$ZY$37, MATCH('Komoditas besar Nasional'!D$2,'raw-all-komoditas'!$B$3:$B$37,0), MATCH('Komoditas besar Nasional'!$B11,'raw-all-komoditas'!$B$3:$ZY$3,0)) -> 65585 | E11: =INDEX('raw-all-komoditas'!$B$3:$ZY$37, MATCH('Komoditas besar Nasional'!E$2,'raw-all-komoditas'!$B$3:$B$37,0), MATCH('Komoditas besar Nasional'!$B11,'raw-all-komoditas'!$B$3:$ZY$3,0)) -> 233917 | F11: =INDEX('raw-all-komoditas'!$B$3:$ZY$37, MATCH('Komoditas besar Nasional'!F$2,'raw-all-komoditas'!$B$3:$B$37,0), MATCH('Komoditas besar Nasional'!$B11,'raw-all-komoditas'!$B$3:$ZY$3,0)) -> 323 | G11: =INDEX('raw-all-komoditas'!$B$3:$ZY$37, MATCH('Komoditas besar Nasional'!G$2,'raw-all-komoditas'!$B$3:$B$37,0), MATCH('Komoditas besar Nasional'!$B11,'raw-all-komoditas'!$B$3:$ZY$3,0)) -> 18401 | H11: =INDEX('raw-all-komoditas'!$B$3:$ZY$37, MATCH('Komoditas besar Nasional'!H$2,'raw-all-komoditas'!$B$3:$B$37,0), MATCH('Komoditas besar Nasional'!$B11,'raw-all-komoditas'!$B$3:$ZY$3,0)) -> 1197 | I11: =INDEX('raw-all-komoditas'!$B$3:$ZY$37, MATCH('Komoditas besar Nasional'!I$2,'raw-all-komoditas'!$B$3:$B$37,0), MATCH('Komoditas besar Nasional'!$B11,'raw-all-komoditas'!$B$3:$ZY$3,0)) -> 671 | J11: =INDEX('raw-all-komoditas'!$B$3:$ZY$37, MATCH('Komoditas besar Nasional'!J$2,'raw-all-komoditas'!$B$3:$B$37,0), MATCH('Komoditas besar Nasional'!$B11,'raw-all-komoditas'!$B$3:$ZY$3,0)) -> 2193 | ... AJ11: =INDEX('raw-all-komoditas'!$B$3:$ZY$37, MATCH('Komoditas besar Nasional'!AJ$2,'raw-all-komoditas'!$B$3:$B$37,0), MATCH('Komoditas besar Nasional'!$B11,'raw-all-komoditas'!$B$3:$ZY$3,0)) -> 317 | AL11: =INDEX('rank provinsi to commodity'!$B$3:$ZX$37, MATCH(AL$2,'rank provinsi to commodity'!$B$3:$B$37,0),MATCH($B11,'rank provinsi to commodity'!$B$3:$ZX$3,0)) -> 11 | AM11: =INDEX('rank provinsi to commodity'!$B$3:$ZX$37, MATCH(AM$2,'rank provinsi to commodity'!$B$3:$B$37,0),MATCH($B11,'rank provinsi to commodity'!$B$3:$ZX$3,0)) -> 7 | AN11: =INDEX('rank provinsi to commodity'!$B$3:$ZX$37, MATCH(AN$2,'rank provinsi to commodity'!$B$3:$B$37,0),MATCH($B11,'rank provinsi to commodity'!$B$3:$ZX$3,0)) -> 3 | AO11: =INDEX('rank provinsi to commodity'!$B$3:$ZX$37, MATCH(AO$2,'rank provinsi to commodity'!$B$3:$B$37,0),MATCH($B11,'rank provinsi to commodity'!$B$3:$ZX$3,0)) -> 26 | AP11: =INDEX('rank provinsi to commodity'!$B$3:$ZX$37, MATCH(AP$2,'rank provinsi to commodity'!$B$3:$B$37,0),MATCH($B11,'rank provinsi to commodity'!$B$3:$ZX$3,0)) -> 10 | AQ11: =INDEX('rank provinsi to commodity'!$B$3:$ZX$37, MATCH(AQ$2,'rank provinsi to commodity'!$B$3:$B$37,0),MATCH($B11,'rank provinsi to commodity'!$B$3:$ZX$3,0)) -> 16 | AR11: =INDEX('rank provinsi to commodity'!$B$3:$ZX$37, MATCH(AR$2,'rank provinsi to commodity'!$B$3:$B$37,0),MATCH($B11,'rank provinsi to commodity'!$B$3:$ZX$3,0)) -> 19 | AS11: =INDEX('rank provinsi to commodity'!$B$3:$ZX$37, MATCH(AS$2,'rank provinsi to commodity'!$B$3:$B$37,0),MATCH($B11,'rank provinsi to commodity'!$B$3:$ZX$3,0)) -> 15 | ... BS11: =INDEX('rank provinsi to commodity'!$B$3:$ZX$37, MATCH(BS$2,'rank provinsi to commodity'!$B$3:$B$37,0),MATCH($B11,'rank provinsi to commodity'!$B$3:$ZX$3,0)) -> 27
A12: Tanaman Sayuran | B12: Bawang Putih (Ton) | C12: =INDEX('raw-all-komoditas'!$B$3:$ZY$37, MATCH('Komoditas besar Nasional'!C$2,'raw-all-komoditas'!$B$3:$B$37,0), MATCH('Komoditas besar Nasional'!$B12,'raw-all-komoditas'!$B$3:$ZY$3,0)) -> 20 | D12: =INDEX('raw-all-komoditas'!$B$3:$ZY$37, MATCH('Komoditas besar Nasional'!D$2,'raw-all-komoditas'!$B$3:$B$37,0), MATCH('Komoditas besar Nasional'!$B12,'raw-all-komoditas'!$B$3:$ZY$3,0)) -> 15 | E12: =INDEX('raw-all-komoditas'!$B$3:$ZY$37, MATCH('Komoditas besar Nasional'!E$2,'raw-all-komoditas'!$B$3:$B$37,0), MATCH('Komoditas besar Nasional'!$B12,'raw-all-komoditas'!$B$3:$ZY$3,0)) -> 588 | F12: =INDEX('raw-all-komoditas'!$B$3:$ZY$37, MATCH('Komoditas besar Nasional'!F$2,'raw-all-komoditas'!$B$3:$B$37,0), MATCH('Komoditas besar Nasional'!$B12,'raw-all-komoditas'!$B$3:$ZY$3,0)) -> 0 | G12: =INDEX('raw-all-komoditas'!$B$3:$ZY$37, MATCH('Komoditas besar Nasional'!G$2,'raw-all-komoditas'!$B$3:$B$37,0), MATCH('Komoditas besar Nasional'!$B12,'raw-all-komoditas'!$B$3:$ZY$3,0)) -> 527 | H12: =INDEX('raw-all-komoditas'!$B$3:$ZY$37, MATCH('Komoditas besar Nasional'!H$2,'raw-all-komoditas'!$B$3:$B$37,0), MATCH('Komoditas besar Nasional'!$B12,'raw-all-komoditas'!$B$3:$ZY$3,0)) -> 50 | I12: =INDEX('raw-all-komoditas'!$B$3:$ZY$37, MATCH('Komoditas besar Nasional'!I$2,'raw-all-komoditas'!$B$3:$B$37,0), MATCH('Komoditas besar Nasional'!$B12,'raw-all-komoditas'!$B$3:$ZY$3,0)) -> 15 | J12: =INDEX('raw-all-komoditas'!$B$3:$ZY$37, MATCH('Komoditas besar Nasional'!J$2,'raw-all-komoditas'!$B$3:$B$37,0), MATCH('Komoditas besar Nasional'!$B12,'raw-all-komoditas'!$B$3:$ZY$3,0)) -> 1 | ... AJ12: =INDEX('raw-all-komoditas'!$B$3:$ZY$37, MATCH('Komoditas besar Nasional'!AJ$2,'raw-all-komoditas'!$B$3:$B$37,0), MATCH('Komoditas besar Nasional'!$B12,'raw-all-komoditas'!$B$3:$ZY$3,0)) -> 1 | AL12: =INDEX('rank provinsi to commodity'!$B$3:$ZX$37, MATCH(AL$2,'rank provinsi to commodity'!$B$3:$B$37,0),MATCH($B12,'rank provinsi to commodity'!$B$3:$ZX$3,0)) -> 11 | AM12: =INDEX('rank provinsi to commodity'!$B$3:$ZX$37, MATCH(AM$2,'rank provinsi to commodity'!$B$3:$B$37,0),MATCH($B12,'rank provinsi to commodity'!$B$3:$ZX$3,0)) -> 12 | AN12: =INDEX('rank provinsi to commodity'!$B$3:$ZX$37, MATCH(AN$2,'rank provinsi to commodity'!$B$3:$B$37,0),MATCH($B12,'rank provinsi to commodity'!$B$3:$ZX$3,0)) -> 4 | AO12: =INDEX('rank provinsi to commodity'!$B$3:$ZX$37, MATCH(AO$2,'rank provinsi to commodity'!$B$3:$B$37,0),MATCH($B12,'rank provinsi to commodity'!$B$3:$ZX$3,0)) -> 19 | AP12: =INDEX('rank provinsi to commodity'!$B$3:$ZX$37, MATCH(AP$2,'rank provinsi to commodity'!$B$3:$B$37,0),MATCH($B12,'rank provinsi to commodity'!$B$3:$ZX$3,0)) -> 5 | AQ12: =INDEX('rank provinsi to commodity'!$B$3:$ZX$37, MATCH(AQ$2,'rank provinsi to commodity'!$B$3:$B$37,0),MATCH($B12,'rank provinsi to commodity'!$B$3:$ZX$3,0)) -> 10 | AR12: =INDEX('rank provinsi to commodity'!$B$3:$ZX$37, MATCH(AR$2,'rank provinsi to commodity'!$B$3:$B$37,0),MATCH($B12,'rank provinsi to commodity'!$B$3:$ZX$3,0)) -> 12 | AS12: =INDEX('rank provinsi to commodity'!$B$3:$ZX$37, MATCH(AS$2,'rank provinsi to commodity'!$B$3:$B$37,0),MATCH($B12,'rank provinsi to commodity'!$B$3:$ZX$3,0)) -> 15 | ... BS12: =INDEX('rank provinsi to commodity'!$B$3:$ZX$37, MATCH(BS$2,'rank provinsi to commodity'!$B$3:$B$37,0),MATCH($B12,'rank provinsi to commodity'!$B$3:$ZX$3,0)) -> 15
A13: Tanaman Sayuran | B13: Bawang Daun (Ton) | C13: =INDEX('raw-all-komoditas'!$B$3:$ZY$37, MATCH('Komoditas besar Nasional'!C$2,'raw-all-komoditas'!$B$3:$B$37,0), MATCH('Komoditas besar Nasional'!$B13,'raw-all-komoditas'!$B$3:$ZY$3,0)) -> 1193 | D13: =INDEX('raw-all-komoditas'!$B$3:$ZY$37, MATCH('Komoditas besar Nasional'!D$2,'raw-all-komoditas'!$B$3:$B$37,0), MATCH('Komoditas besar Nasional'!$B13,'raw-all-komoditas'!$B$3:$ZY$3,0)) -> 17669 | E13: =INDEX('raw-all-komoditas'!$B$3:$ZY$37, MATCH('Komoditas besar Nasional'!E$2,'raw-all-komoditas'!$B$3:$B$37,0), MATCH('Komoditas besar Nasional'!$B13,'raw-all-komoditas'!$B$3:$ZY$3,0)) -> 62073 | F13: =INDEX('raw-all-komoditas'!$B$3:$ZY$37, MATCH('Komoditas besar Nasional'!F$2,'raw-all-komoditas'!$B$3:$B$37,0), MATCH('Komoditas besar Nasional'!$B13,'raw-all-komoditas'!$B$3:$ZY$3,0)) -> 17 | G13: =INDEX('raw-all-komoditas'!$B$3:$ZY$37, MATCH('Komoditas besar Nasional'!G$2,'raw-all-komoditas'!$B$3:$B$37,0), MATCH('Komoditas besar Nasional'!$B13,'raw-all-komoditas'!$B$3:$ZY$3,0)) -> 9422 | H13: =INDEX('raw-all-komoditas'!$B$3:$ZY$37, MATCH('Komoditas besar Nasional'!H$2,'raw-all-komoditas'!$B$3:$B$37,0), MATCH('Komoditas besar Nasional'!$B13,'raw-all-komoditas'!$B$3:$ZY$3,0)) -> 3022 | I13: =INDEX('raw-all-komoditas'!$B$3:$ZY$37, MATCH('Komoditas besar Nasional'!I$2,'raw-all-komoditas'!$B$3:$B$37,0), MATCH('Komoditas besar Nasional'!$B13,'raw-all-komoditas'!$B$3:$ZY$3,0)) -> 16360 | J13: =INDEX('raw-all-komoditas'!$B$3:$ZY$37, MATCH('Komoditas besar Nasional'!J$2,'raw-all-komoditas'!$B$3:$B$37,0), MATCH('Komoditas besar Nasional'!$B13,'raw-all-komoditas'!$B$3:$ZY$3,0)) -> 3742 | ... AJ13: =INDEX('raw-all-komoditas'!$B$3:$ZY$37, MATCH('Komoditas besar Nasional'!AJ$2,'raw-all-komoditas'!$B$3:$B$37,0), MATCH('Komoditas besar Nasional'!$B13,'raw-all-komoditas'!$B$3:$ZY$3,0)) -> 1501 | AL13: =INDEX('rank provinsi to commodity'!$B$3:$ZX$37, MATCH(AL$2,'rank provinsi to commodity'!$B$3:$B$37,0),MATCH($B13,'rank provinsi to commodity'!$B$3:$ZX$3,0)) -> 18 | AM13: =INDEX('rank provinsi to commodity'!$B$3:$ZX$37, MATCH(AM$2,'rank provinsi to commodity'!$B$3:$B$37,0),MATCH($B13,'rank provinsi to commodity'!$B$3:$ZX$3,0)) -> 7 | AN13: =INDEX('rank provinsi to commodity'!$B$3:$ZX$37, MATCH(AN$2,'rank provinsi to commodity'!$B$3:$B$37,0),MATCH($B13,'rank provinsi to commodity'!$B$3:$ZX$3,0)) -> 4 | AO13: =INDEX('rank provinsi to commodity'!$B$3:$ZX$37, MATCH(AO$2,'rank provinsi to commodity'!$B$3:$B$37,0),MATCH($B13,'rank provinsi to commodity'!$B$3:$ZX$3,0)) -> 33 | AP13: =INDEX('rank provinsi to commodity'!$B$3:$ZX$37, MATCH(AP$2,'rank provinsi to commodity'!$B$3:$B$37,0),MATCH($B13,'rank provinsi to commodity'!$B$3:$ZX$3,0)) -> 9 | AQ13: =INDEX('rank provinsi to commodity'!$B$3:$ZX$37, MATCH(AQ$2,'rank provinsi to commodity'!$B$3:$B$37,0),MATCH($B13,'rank provinsi to commodity'!$B$3:$ZX$3,0)) -> 12 | AR13: =INDEX('rank provinsi to commodity'!$B$3:$ZX$37, MATCH(AR$2,'rank provinsi to commodity'!$B$3:$B$37,0),MATCH($B13,'rank provinsi to commodity'!$B$3:$ZX$3,0)) -> 8 | AS13: =INDEX('rank provinsi to commodity'!$B$3:$ZX$37, MATCH(AS$2,'rank provinsi to commodity'!$B$3:$B$37,0),MATCH($B13,'rank provinsi to commodity'!$B$3:$ZX$3,0)) -> 11 | ... BS13: =INDEX('rank provinsi to commodity'!$B$3:$ZX$37, MATCH(BS$2,'rank provinsi to commodity'!$B$3:$B$37,0),MATCH($B13,'rank provinsi to commodity'!$B$3:$ZX$3,0)) -> 16
A14: Tanaman Sayuran | B14: Bayam (Ton) | C14: =INDEX('raw-all-komoditas'!$B$3:$ZY$37, MATCH('Komoditas besar Nasional'!C$2,'raw-all-komoditas'!$B$3:$B$37,0), MATCH('Komoditas besar Nasional'!$B14,'raw-all-komoditas'!$B$3:$ZY$3,0)) -> 4275 | D14: =INDEX('raw-all-komoditas'!$B$3:$ZY$37, MATCH('Komoditas besar Nasional'!D$2,'raw-all-komoditas'!$B$3:$B$37,0), MATCH('Komoditas besar Nasional'!$B14,'raw-all-komoditas'!$B$3:$ZY$3,0)) -> 16895 | E14: =INDEX('raw-all-komoditas'!$B$3:$ZY$37, MATCH('Komoditas besar Nasional'!E$2,'raw-all-komoditas'!$B$3:$B$37,0), MATCH('Komoditas besar Nasional'!$B14,'raw-all-komoditas'!$B$3:$ZY$3,0)) -> 6570 | F14: =INDEX('raw-all-komoditas'!$B$3:$ZY$37, MATCH('Komoditas besar Nasional'!F$2,'raw-all-komoditas'!$B$3:$B$37,0), MATCH('Komoditas besar Nasional'!$B14,'raw-all-komoditas'!$B$3:$ZY$3,0)) -> 10094 | G14: =INDEX('raw-all-komoditas'!$B$3:$ZY$37, MATCH('Komoditas besar Nasional'!G$2,'raw-all-komoditas'!$B$3:$B$37,0), MATCH('Komoditas besar Nasional'!$B14,'raw-all-komoditas'!$B$3:$ZY$3,0)) -> 5734 | H14: =INDEX('raw-all-komoditas'!$B$3:$ZY$37, MATCH('Komoditas besar Nasional'!H$2,'raw-all-komoditas'!$B$3:$B$37,0), MATCH('Komoditas besar Nasional'!$B14,'raw-all-komoditas'!$B$3:$ZY$3,0)) -> 3043 | I14: =INDEX('raw-all-komoditas'!$B$3:$ZY$37, MATCH('Komoditas besar Nasional'!I$2,'raw-all-komoditas'!$B$3:$B$37,0), MATCH('Komoditas besar Nasional'!$B14,'raw-all-komoditas'!$B$3:$ZY$3,0)) -> 554 | J14: =INDEX('raw-all-komoditas'!$B$3:$ZY$37, MATCH('Komoditas besar Nasional'!J$2,'raw-all-komoditas'!$B$3:$B$37,0), MATCH('Komoditas besar Nasional'!$B14,'raw-all-komoditas'!$B$3:$ZY$3,0)) -> 7605 | ... AJ14: =INDEX('raw-all-komoditas'!$B$3:$ZY$37, MATCH('Komoditas besar Nasional'!AJ$2,'raw-all-komoditas'!$B$3:$B$37,0), MATCH('Komoditas besar Nasional'!$B14,'raw-all-komoditas'!$B$3:$ZY$3,0)) -> 4038 | AL14: =INDEX('rank provinsi to commodity'!$B$3:$ZX$37, MATCH(AL$2,'rank provinsi to commodity'!$B$3:$B$37,0),MATCH($B14,'rank provinsi to commodity'!$B$3:$ZX$3,0)) -> 13 | AM14: =INDEX('rank provinsi to commodity'!$B$3:$ZX$37, MATCH(AM$2,'rank provinsi to commodity'!$B$3:$B$37,0),MATCH($B14,'rank provinsi to commodity'!$B$3:$ZX$3,0)) -> 2 | AN14: =INDEX('rank provinsi to commodity'!$B$3:$ZX$37, MATCH(AN$2,'rank provinsi to commodity'!$B$3:$B$37,0),MATCH($B14,'rank provinsi to commodity'!$B$3:$ZX$3,0)) -> 8 | AO14: =INDEX('rank provinsi to commodity'!$B$3:$ZX$37, MATCH(AO$2,'rank provinsi to commodity'!$B$3:$B$37,0),MATCH($B14,'rank provinsi to commodity'!$B$3:$ZX$3,0)) -> 5 | AP14: =INDEX('rank provinsi to commodity'!$B$3:$ZX$37, MATCH(AP$2,'rank provinsi to commodity'!$B$3:$B$37,0),MATCH($B14,'rank provinsi to commodity'!$B$3:$ZX$3,0)) -> 9 | AQ14: =INDEX('rank provinsi to commodity'!$B$3:$ZX$37, MATCH(AQ$2,'rank provinsi to commodity'!$B$3:$B$37,0),MATCH($B14,'rank provinsi to commodity'!$B$3:$ZX$3,0)) -> 18 | AR14: =INDEX('rank provinsi to commodity'!$B$3:$ZX$37, MATCH(AR$2,'rank provinsi to commodity'!$B$3:$B$37,0),MATCH($B14,'rank provinsi to commodity'!$B$3:$ZX$3,0)) -> 32 | AS14: =INDEX('rank provinsi to commodity'!$B$3:$ZX$37, MATCH(AS$2,'rank provinsi to commodity'!$B$3:$B$37,0),MATCH($B14,'rank provinsi to commodity'!$B$3:$ZX$3,0)) -> 7 | ... BS14: =INDEX('rank provinsi to commodity'!$B$3:$ZX$37, MATCH(BS$2,'rank provinsi to commodity'!$B$3:$B$37,0),MATCH($B14,'rank provinsi to commodity'!$B$3:$ZX$3,0)) -> 14
... A168: Peternakan (Susu) | B168: Susu (Ton, all) | C168: =INDEX('raw-all-komoditas'!$B$3:$ZY$37, MATCH('Komoditas besar Nasional'!C$2,'raw-all-komoditas'!$B$3:$B$37,0), MATCH('Komoditas besar Nasional'!$B168,'raw-all-komoditas'!$B$3:$ZY$3,0)) -> 1.8 | D168: =INDEX('raw-all-komoditas'!$B$3:$ZY$37, MATCH('Komoditas besar Nasional'!D$2,'raw-all-komoditas'!$B$3:$B$37,0), MATCH('Komoditas besar Nasional'!$B168,'raw-all-komoditas'!$B$3:$ZY$3,0)) -> 9234.4 | E168: =INDEX('raw-all-komoditas'!$B$3:$ZY$37, MATCH('Komoditas besar Nasional'!E$2,'raw-all-komoditas'!$B$3:$B$37,0), MATCH('Komoditas besar Nasional'!$B168,'raw-all-komoditas'!$B$3:$ZY$3,0)) -> 965.7 | F168: =INDEX('raw-all-komoditas'!$B$3:$ZY$37, MATCH('Komoditas besar Nasional'!F$2,'raw-all-komoditas'!$B$3:$B$37,0), MATCH('Komoditas besar Nasional'!$B168,'raw-all-komoditas'!$B$3:$ZY$3,0)) -> 29.2 | G168: =INDEX('raw-all-komoditas'!$B$3:$ZY$37, MATCH('Komoditas besar Nasional'!G$2,'raw-all-komoditas'!$B$3:$B$37,0), MATCH('Komoditas besar Nasional'!$B168,'raw-all-komoditas'!$B$3:$ZY$3,0)) -> 3.9 | H168: =INDEX('raw-all-komoditas'!$B$3:$ZY$37, MATCH('Komoditas besar Nasional'!H$2,'raw-all-komoditas'!$B$3:$B$37,0), MATCH('Komoditas besar Nasional'!$B168,'raw-all-komoditas'!$B$3:$ZY$3,0)) -> 7.5 | I168: =INDEX('raw-all-komoditas'!$B$3:$ZY$37, MATCH('Komoditas besar Nasional'!I$2,'raw-all-komoditas'!$B$3:$B$37,0), MATCH('Komoditas besar Nasional'!$B168,'raw-all-komoditas'!$B$3:$ZY$3,0)) -> 23.1 | J168: =INDEX('raw-all-komoditas'!$B$3:$ZY$37, MATCH('Komoditas besar Nasional'!J$2,'raw-all-komoditas'!$B$3:$B$37,0), MATCH('Komoditas besar Nasional'!$B168,'raw-all-komoditas'!$B$3:$ZY$3,0)) -> 3778.8 | ... AJ168: =INDEX('raw-all-komoditas'!$B$3:$ZY$37, MATCH('Komoditas besar Nasional'!AJ$2,'raw-all-komoditas'!$B$3:$B$37,0), MATCH('Komoditas besar Nasional'!$B168,'raw-all-komoditas'!$B$3:$ZY$3,0)) -> 0 | AL168: =INDEX('rank provinsi to commodity'!$B$3:$ZX$37, MATCH(AL$2,'rank provinsi to commodity'!$B$3:$B$37,0),MATCH($B168,'rank provinsi to commodity'!$B$3:$ZX$3,0)) -> 20 | AM168: =INDEX('rank provinsi to commodity'!$B$3:$ZX$37, MATCH(AM$2,'rank provinsi to commodity'!$B$3:$B$37,0),MATCH($B168,'rank provinsi to commodity'!$B$3:$ZX$3,0)) -> 4 | AN168: =INDEX('rank provinsi to commodity'!$B$3:$ZX$37, MATCH(AN$2,'rank provinsi to commodity'!$B$3:$B$37,0),MATCH($B168,'rank provinsi to commodity'!$B$3:$ZX$3,0)) -> 9 | AO168: =INDEX('rank provinsi to commodity'!$B$3:$ZX$37, MATCH(AO$2,'rank provinsi to commodity'!$B$3:$B$37,0),MATCH($B168,'rank provinsi to commodity'!$B$3:$ZX$3,0)) -> 15 | AP168: =INDEX('rank provinsi to commodity'!$B$3:$ZX$37, MATCH(AP$2,'rank provinsi to commodity'!$B$3:$B$37,0),MATCH($B168,'rank provinsi to commodity'!$B$3:$ZX$3,0)) -> 19 | AQ168: =INDEX('rank provinsi to commodity'!$B$3:$ZX$37, MATCH(AQ$2,'rank provinsi to commodity'!$B$3:$B$37,0),MATCH($B168,'rank provinsi to commodity'!$B$3:$ZX$3,0)) -> 18 | AR168: =INDEX('rank provinsi to commodity'!$B$3:$ZX$37, MATCH(AR$2,'rank provinsi to commodity'!$B$3:$B$37,0),MATCH($B168,'rank provinsi to commodity'!$B$3:$ZX$3,0)) -> 16 | AS168: =INDEX('rank provinsi to commodity'!$B$3:$ZX$37, MATCH(AS$2,'rank provinsi to commodity'!$B$3:$B$37,0),MATCH($B168,'rank provinsi to commodity'!$B$3:$ZX$3,0)) -> 5 | ... BS168: =INDEX('rank provinsi to commodity'!$B$3:$ZX$37, MATCH(BS$2,'rank provinsi to commodity'!$B$3:$B$37,0),MATCH($B168,'rank provinsi to commodity'!$B$3:$ZX$3,0)) -> 21
A169: Perikanan Tangkap Laut (Milyar) | B169: ALU-ALU ; tangkap | C169: =INDEX('raw-all-komoditas'!$B$3:$ZY$37, MATCH('Komoditas besar Nasional'!C$2,'raw-all-komoditas'!$B$3:$B$37,0), MATCH('Komoditas besar Nasional'!$B169,'raw-all-komoditas'!$B$3:$ZY$3,0)) -> 45.306744 | D169: =INDEX('raw-all-komoditas'!$B$3:$ZY$37, MATCH('Komoditas besar Nasional'!D$2,'raw-all-komoditas'!$B$3:$B$37,0), MATCH('Komoditas besar Nasional'!$B169,'raw-all-komoditas'!$B$3:$ZY$3,0)) -> 92.59835 | E169: =INDEX('raw-all-komoditas'!$B$3:$ZY$37, MATCH('Komoditas besar Nasional'!E$2,'raw-all-komoditas'!$B$3:$B$37,0), MATCH('Komoditas besar Nasional'!$B169,'raw-all-komoditas'!$B$3:$ZY$3,0)) -> 153.23194 | F169: =INDEX('raw-all-komoditas'!$B$3:$ZY$37, MATCH('Komoditas besar Nasional'!F$2,'raw-all-komoditas'!$B$3:$B$37,0), MATCH('Komoditas besar Nasional'!$B169,'raw-all-komoditas'!$B$3:$ZY$3,0)) -> 0 | G169: =INDEX('raw-all-komoditas'!$B$3:$ZY$37, MATCH('Komoditas besar Nasional'!G$2,'raw-all-komoditas'!$B$3:$B$37,0), MATCH('Komoditas besar Nasional'!$B169,'raw-all-komoditas'!$B$3:$ZY$3,0)) -> 19.926734 | H169: =INDEX('raw-all-komoditas'!$B$3:$ZY$37, MATCH('Komoditas besar Nasional'!H$2,'raw-all-komoditas'!$B$3:$B$37,0), MATCH('Komoditas besar Nasional'!$B169,'raw-all-komoditas'!$B$3:$ZY$3,0)) -> 0 | I169: =INDEX('raw-all-komoditas'!$B$3:$ZY$37, MATCH('Komoditas besar Nasional'!I$2,'raw-all-komoditas'!$B$3:$B$37,0), MATCH('Komoditas besar Nasional'!$B169,'raw-all-komoditas'!$B$3:$ZY$3,0)) -> 0 | J169: =INDEX('raw-all-komoditas'!$B$3:$ZY$37, MATCH('Komoditas besar Nasional'!J$2,'raw-all-komoditas'!$B$3:$B$37,0), MATCH('Komoditas besar Nasional'!$B169,'raw-all-komoditas'!$B$3:$ZY$3,0)) -> 21.141357 | ... AJ169: =INDEX('raw-all-komoditas'!$B$3:$ZY$37, MATCH('Komoditas besar Nasional'!AJ$2,'raw-all-komoditas'!$B$3:$B$37,0), MATCH('Komoditas besar Nasional'!$B169,'raw-all-komoditas'!$B$3:$ZY$3,0)) -> 24.613739 | AL169: =INDEX('rank provinsi to commodity'!$B$3:$ZX$37, MATCH(AL$2,'rank provinsi to commodity'!$B$3:$B$37,0),MATCH($B169,'rank provinsi to commodity'!$B$3:$ZX$3,0)) -> 8 | AM169: =INDEX('rank provinsi to commodity'!$B$3:$ZX$37, MATCH(AM$2,'rank provinsi to commodity'!$B$3:$B$37,0),MATCH($B169,'rank provinsi to commodity'!$B$3:$ZX$3,0)) -> 3 | AN169: =INDEX('rank provinsi to commodity'!$B$3:$ZX$37, MATCH(AN$2,'rank provinsi to commodity'!$B$3:$B$37,0),MATCH($B169,'rank provinsi to commodity'!$B$3:$ZX$3,0)) -> 1 | AO169: =INDEX('rank provinsi to commodity'!$B$3:$ZX$37, MATCH(AO$2,'rank provinsi to commodity'!$B$3:$B$37,0),MATCH($B169,'rank provinsi to commodity'!$B$3:$ZX$3,0)) -> 30 | AP169: =INDEX('rank provinsi to commodity'!$B$3:$ZX$37, MATCH(AP$2,'rank provinsi to commodity'!$B$3:$B$37,0),MATCH($B169,'rank provinsi to commodity'!$B$3:$ZX$3,0)) -> 11 | AQ169: =INDEX('rank provinsi to commodity'!$B$3:$ZX$37, MATCH(AQ$2,'rank provinsi to commodity'!$B$3:$B$37,0),MATCH($B169,'rank provinsi to commodity'!$B$3:$ZX$3,0)) -> 30 | AR169: =INDEX('rank provinsi to commodity'!$B$3:$ZX$37, MATCH(AR$2,'rank provinsi to commodity'!$B$3:$B$37,0),MATCH($B169,'rank provinsi to commodity'!$B$3:$ZX$3,0)) -> 30 | AS169: =INDEX('rank provinsi to commodity'!$B$3:$ZX$37, MATCH(AS$2,'rank provinsi to commodity'!$B$3:$B$37,0),MATCH($B169,'rank provinsi to commodity'!$B$3:$ZX$3,0)) -> 10 | ... BS169: =INDEX('rank provinsi to commodity'!$B$3:$ZX$37, MATCH(BS$2,'rank provinsi to commodity'!$B$3:$B$37,0),MATCH($B169,'rank provinsi to commodity'!$B$3:$ZX$3,0)) -> 9 | BU169: PERIKANAN TANGKAP LAUT (Ton) | BV169: ALU-ALU (Ton) | BW169: =INDEX('raw-all-komoditas'!$B$3:$ZY$37, MATCH('Komoditas besar Nasional'!BW$2,'raw-all-komoditas'!$B$3:$B$37,0), MATCH('Komoditas besar Nasional'!$BV169,'raw-all-komoditas'!$B$3:$ZY$3,0)) -> 2471 | BX169: =INDEX('raw-all-komoditas'!$B$3:$ZY$37, MATCH('Komoditas besar Nasional'!BX$2,'raw-all-komoditas'!$B$3:$B$37,0), MATCH('Komoditas besar Nasional'!$BV169,'raw-all-komoditas'!$B$3:$ZY$3,0)) -> 2757 | BY169: =INDEX('raw-all-komoditas'!$B$3:$ZY$37, MATCH('Komoditas besar Nasional'!BY$2,'raw-all-komoditas'!$B$3:$B$37,0), MATCH('Komoditas besar Nasional'!$BV169,'raw-all-komoditas'!$B$3:$ZY$3,0)) -> 6958 | BZ169: =INDEX('raw-all-komoditas'!$B$3:$ZY$37, MATCH('Komoditas besar Nasional'!BZ$2,'raw-all-komoditas'!$B$3:$B$37,0), MATCH('Komoditas besar Nasional'!$BV169,'raw-all-komoditas'!$B$3:$ZY$3,0)) -> 0 | CA169: =INDEX('raw-all-komoditas'!$B$3:$ZY$37, MATCH('Komoditas besar Nasional'!CA$2,'raw-all-komoditas'!$B$3:$B$37,0), MATCH('Komoditas besar Nasional'!$BV169,'raw-all-komoditas'!$B$3:$ZY$3,0)) -> 997 | CB169: =INDEX('raw-all-komoditas'!$B$3:$ZY$37, MATCH('Komoditas besar Nasional'!CB$2,'raw-all-komoditas'!$B$3:$B$37,0), MATCH('Komoditas besar Nasional'!$BV169,'raw-all-komoditas'!$B$3:$ZY$3,0)) -> 0 | CC169: =INDEX('raw-all-komoditas'!$B$3:$ZY$37, MATCH('Komoditas besar Nasional'!CC$2,'raw-all-komoditas'!$B$3:$B$37,0), MATCH('Komoditas besar Nasional'!$BV169,'raw-all-komoditas'!$B$3:$ZY$3,0)) -> 0 | CD169: =INDEX('raw-all-komoditas'!$B$3:$ZY$37, MATCH('Komoditas besar Nasional'!CD$2,'raw-all-komoditas'!$B$3:$B$37,0), MATCH('Komoditas besar Nasional'!$BV169,'raw-all-komoditas'!$B$3:$ZY$3,0)) -> 1004 | ... DD169: =INDEX('raw-all-komoditas'!$B$3:$ZY$37, MATCH('Komoditas besar Nasional'!DD$2,'raw-all-komoditas'!$B$3:$B$37,0), MATCH('Komoditas besar Nasional'!$BV169,'raw-all-komoditas'!$B$3:$ZY$3,0)) -> 569 | DF169: =IF(C169>=250, "Lebih dari 250M", "Kurang dari 250M") -> Kurang dari 250M | DG169: =IF(D169>=250, "Lebih dari 250M", "Kurang dari 250M") -> Kurang dari 250M | DH169: =IF(E169>=250, "Lebih dari 250M", "Kurang dari 250M") -> Kurang dari 250M | DI169: =IF(F169>=250, "Lebih dari 250M", "Kurang dari 250M") -> Kurang dari 250M | DJ169: =IF(G169>=250, "Lebih dari 250M", "Kurang dari 250M") -> Kurang dari 250M | DK169: =IF(H169>=250, "Lebih dari 250M", "Kurang dari 250M") -> Kurang dari 250M | DL169: =IF(I169>=250, "Lebih dari 250M", "Kurang dari 250M") -> Kurang dari 250M | DM169: =IF(J169>=250, "Lebih dari 250M", "Kurang dari 250M") -> Kurang dari 250M | ... EM169: =IF(AJ169>=250, "Lebih dari 250M", "Kurang dari 250M") -> Kurang dari 250M
A170: Perikanan Tangkap Laut (Milyar) | B170: AYAM-AYAM ; tangkap | C170: =INDEX('raw-all-komoditas'!$B$3:$ZY$37, MATCH('Komoditas besar Nasional'!C$2,'raw-all-komoditas'!$B$3:$B$37,0), MATCH('Komoditas besar Nasional'!$B170,'raw-all-komoditas'!$B$3:$ZY$3,0)) -> 68.654179 | D170: =INDEX('raw-all-komoditas'!$B$3:$ZY$37, MATCH('Komoditas besar Nasional'!D$2,'raw-all-komoditas'!$B$3:$B$37,0), MATCH('Komoditas besar Nasional'!$B170,'raw-all-komoditas'!$B$3:$ZY$3,0)) -> 1.885286 | E170: =INDEX('raw-all-komoditas'!$B$3:$ZY$37, MATCH('Komoditas besar Nasional'!E$2,'raw-all-komoditas'!$B$3:$B$37,0), MATCH('Komoditas besar Nasional'!$B170,'raw-all-komoditas'!$B$3:$ZY$3,0)) -> 6.508401 | F170: =INDEX('raw-all-komoditas'!$B$3:$ZY$37, MATCH('Komoditas besar Nasional'!F$2,'raw-all-komoditas'!$B$3:$B$37,0), MATCH('Komoditas besar Nasional'!$B170,'raw-all-komoditas'!$B$3:$ZY$3,0)) -> 0 | G170: =INDEX('raw-all-komoditas'!$B$3:$ZY$37, MATCH('Komoditas besar Nasional'!G$2,'raw-all-komoditas'!$B$3:$B$37,0), MATCH('Komoditas besar Nasional'!$B170,'raw-all-komoditas'!$B$3:$ZY$3,0)) -> 0 | H170: =INDEX('raw-all-komoditas'!$B$3:$ZY$37, MATCH('Komoditas besar Nasional'!H$2,'raw-all-komoditas'!$B$3:$B$37,0), MATCH('Komoditas besar Nasional'!$B170,'raw-all-komoditas'!$B$3:$ZY$3,0)) -> 0 | I170: =INDEX('raw-all-komoditas'!$B$3:$ZY$37, MATCH('Komoditas besar Nasional'!I$2,'raw-all-komoditas'!$B$3:$B$37,0), MATCH('Komoditas besar Nasional'!$B170,'raw-all-komoditas'!$B$3:$ZY$3,0)) -> 0 | J170: =INDEX('raw-all-komoditas'!$B$3:$ZY$37, MATCH('Komoditas besar Nasional'!J$2,'raw-all-komoditas'!$B$3:$B$37,0), MATCH('Komoditas besar Nasional'!$B170,'raw-all-komoditas'!$B$3:$ZY$3,0)) -> 1.26 | ... AJ170: =INDEX('raw-all-komoditas'!$B$3:$ZY$37, MATCH('Komoditas besar Nasional'!AJ$2,'raw-all-komoditas'!$B$3:$B$37,0), MATCH('Komoditas besar Nasional'!$B170,'raw-all-komoditas'!$B$3:$ZY$3,0)) -> 0 | AL170: =INDEX('rank provinsi to commodity'!$B$3:$ZX$37, MATCH(AL$2,'rank provinsi to commodity'!$B$3:$B$37,0),MATCH($B170,'rank provinsi to commodity'!$B$3:$ZX$3,0)) -> 2 | AM170: =INDEX('rank provinsi to commodity'!$B$3:$ZX$37, MATCH(AM$2,'rank provinsi to commodity'!$B$3:$B$37,0),MATCH($B170,'rank provinsi to commodity'!$B$3:$ZX$3,0)) -> 10 | AN170: =INDEX('rank provinsi to commodity'!$B$3:$ZX$37, MATCH(AN$2,'rank provinsi to commodity'!$B$3:$B$37,0),MATCH($B170,'rank provinsi to commodity'!$B$3:$ZX$3,0)) -> 7 | AO170: =INDEX('rank provinsi to commodity'!$B$3:$ZX$37, MATCH(AO$2,'rank provinsi to commodity'!$B$3:$B$37,0),MATCH($B170,'rank provinsi to commodity'!$B$3:$ZX$3,0)) -> 22 | AP170: =INDEX('rank provinsi to commodity'!$B$3:$ZX$37, MATCH(AP$2,'rank provinsi to commodity'!$B$3:$B$37,0),MATCH($B170,'rank provinsi to commodity'!$B$3:$ZX$3,0)) -> 22 | AQ170: =INDEX('rank provinsi to commodity'!$B$3:$ZX$37, MATCH(AQ$2,'rank provinsi to commodity'!$B$3:$B$37,0),MATCH($B170,'rank provinsi to commodity'!$B$3:$ZX$3,0)) -> 22 | AR170: =INDEX('rank provinsi to commodity'!$B$3:$ZX$37, MATCH(AR$2,'rank provinsi to commodity'!$B$3:$B$37,0),MATCH($B170,'rank provinsi to commodity'!$B$3:$ZX$3,0)) -> 22 | AS170: =INDEX('rank provinsi to commodity'!$B$3:$ZX$37, MATCH(AS$2,'rank provinsi to commodity'!$B$3:$B$37,0),MATCH($B170,'rank provinsi to commodity'!$B$3:$ZX$3,0)) -> 13 | ... BS170: =INDEX('rank provinsi to commodity'!$B$3:$ZX$37, MATCH(BS$2,'rank provinsi to commodity'!$B$3:$B$37,0),MATCH($B170,'rank provinsi to commodity'!$B$3:$ZX$3,0)) -> 22 | BU170: =BU169 -> PERIKANAN TANGKAP LAUT (Ton) | BV170: AYAM-AYAM (Ton) | BW170: =INDEX('raw-all-komoditas'!$B$3:$ZY$37, MATCH('Komoditas besar Nasional'!BW$2,'raw-all-komoditas'!$B$3:$B$37,0), MATCH('Komoditas besar Nasional'!$BV170,'raw-all-komoditas'!$B$3:$ZY$3,0)) -> 1833 | BX170: =INDEX('raw-all-komoditas'!$B$3:$ZY$37, MATCH('Komoditas besar Nasional'!BX$2,'raw-all-komoditas'!$B$3:$B$37,0), MATCH('Komoditas besar Nasional'!$BV170,'raw-all-komoditas'!$B$3:$ZY$3,0)) -> 97 | BY170: =INDEX('raw-all-komoditas'!$B$3:$ZY$37, MATCH('Komoditas besar Nasional'!BY$2,'raw-all-komoditas'!$B$3:$B$37,0), MATCH('Komoditas besar Nasional'!$BV170,'raw-all-komoditas'!$B$3:$ZY$3,0)) -> 1447 | BZ170: =INDEX('raw-all-komoditas'!$B$3:$ZY$37, MATCH('Komoditas besar Nasional'!BZ$2,'raw-all-komoditas'!$B$3:$B$37,0), MATCH('Komoditas besar Nasional'!$BV170,'raw-all-komoditas'!$B$3:$ZY$3,0)) -> 0 | CA170: =INDEX('raw-all-komoditas'!$B$3:$ZY$37, MATCH('Komoditas besar Nasional'!CA$2,'raw-all-komoditas'!$B$3:$B$37,0), MATCH('Komoditas besar Nasional'!$BV170,'raw-all-komoditas'!$B$3:$ZY$3,0)) -> 0 | CB170: =INDEX('raw-all-komoditas'!$B$3:$ZY$37, MATCH('Komoditas besar Nasional'!CB$2,'raw-all-komoditas'!$B$3:$B$37,0), MATCH('Komoditas besar Nasional'!$BV170,'raw-all-komoditas'!$B$3:$ZY$3,0)) -> 0 | CC170: =INDEX('raw-all-komoditas'!$B$3:$ZY$37, MATCH('Komoditas besar Nasional'!CC$2,'raw-all-komoditas'!$B$3:$B$37,0), MATCH('Komoditas besar Nasional'!$BV170,'raw-all-komoditas'!$B$3:$ZY$3,0)) -> 0 | CD170: =INDEX('raw-all-komoditas'!$B$3:$ZY$37, MATCH('Komoditas besar Nasional'!CD$2,'raw-all-komoditas'!$B$3:$B$37,0), MATCH('Komoditas besar Nasional'!$BV170,'raw-all-komoditas'!$B$3:$ZY$3,0)) -> 63 | ... DD170: =INDEX('raw-all-komoditas'!$B$3:$ZY$37, MATCH('Komoditas besar Nasional'!DD$2,'raw-all-komoditas'!$B$3:$B$37,0), MATCH('Komoditas besar Nasional'!$BV170,'raw-all-komoditas'!$B$3:$ZY$3,0)) -> 0 | DF170: =IF(C170>=250, "Lebih dari 250M", "Kurang dari 250M") -> Kurang dari 250M | DG170: =IF(D170>=250, "Lebih dari 250M", "Kurang dari 250M") -> Kurang dari 250M | DH170: =IF(E170>=250, "Lebih dari 250M", "Kurang dari 250M") -> Kurang dari 250M | DI170: =IF(F170>=250, "Lebih dari 250M", "Kurang dari 250M") -> Kurang dari 250M | DJ170: =IF(G170>=250, "Lebih dari 250M", "Kurang dari 250M") -> Kurang dari 250M | DK170: =IF(H170>=250, "Lebih dari 250M", "Kurang dari 250M") -> Kurang dari 250M | DL170: =IF(I170>=250, "Lebih dari 250M", "Kurang dari 250M") -> Kurang dari 250M | DM170: =IF(J170>=250, "Lebih dari 250M", "Kurang dari 250M") -> Kurang dari 250M | ... EM170: =IF(AJ170>=250, "Lebih dari 250M", "Kurang dari 250M") -> Kurang dari 250M
